[2025-02-25 09:40:51,604: WARNING/MainProcess] /usr/local/lib/python3.10/site-packages/celery/worker/consumer/consumer.py:508: CPendingDeprecationWarning: The broker_connection_retry configuration setting will no longer determine
whether broker connection retries are made during startup in Celery 6.0 and above.
If you wish to retain the existing behavior for retrying connections on startup,
you should set broker_connection_retry_on_startup to True.
  warnings.warn(

[2025-02-25 09:40:52,049: ERROR/MainProcess] consumer: Cannot connect to redis://redis:6379//: Error -3 connecting to redis:6379. Temporary failure in name resolution..
Trying again in 2.00 seconds... (1/100)

[2025-02-25 09:40:54,459: ERROR/MainProcess] consumer: Cannot connect to redis://redis:6379//: Error -3 connecting to redis:6379. Temporary failure in name resolution..
Trying again in 4.00 seconds... (2/100)

[2025-02-25 09:40:59,066: ERROR/MainProcess] consumer: Cannot connect to redis://redis:6379//: Error -3 connecting to redis:6379. Temporary failure in name resolution..
Trying again in 6.00 seconds... (3/100)

[2025-02-25 09:46:41,036: WARNING/MainProcess] /usr/local/lib/python3.10/site-packages/celery/worker/consumer/consumer.py:508: CPendingDeprecationWarning: The broker_connection_retry configuration setting will no longer determine
whether broker connection retries are made during startup in Celery 6.0 and above.
If you wish to retain the existing behavior for retrying connections on startup,
you should set broker_connection_retry_on_startup to True.
  warnings.warn(

[2025-02-25 09:46:41,441: ERROR/MainProcess] consumer: Cannot connect to redis://redis:6379//: Error -3 connecting to redis:6379. Temporary failure in name resolution..
Trying again in 2.00 seconds... (1/100)

[2025-02-25 09:46:44,161: ERROR/MainProcess] consumer: Cannot connect to redis://redis:6379//: Error -3 connecting to redis:6379. Temporary failure in name resolution..
Trying again in 4.00 seconds... (2/100)

[2025-02-25 09:46:48,547: ERROR/MainProcess] consumer: Cannot connect to redis://redis:6379//: Error -3 connecting to redis:6379. Temporary failure in name resolution..
Trying again in 6.00 seconds... (3/100)

[2025-02-25 09:48:44,069: WARNING/MainProcess] /usr/local/lib/python3.10/site-packages/celery/worker/consumer/consumer.py:508: CPendingDeprecationWarning: The broker_connection_retry configuration setting will no longer determine
whether broker connection retries are made during startup in Celery 6.0 and above.
If you wish to retain the existing behavior for retrying connections on startup,
you should set broker_connection_retry_on_startup to True.
  warnings.warn(

[2025-02-25 09:48:44,492: ERROR/MainProcess] consumer: Cannot connect to redis://redis:6379//: Error -3 connecting to redis:6379. Temporary failure in name resolution..
Trying again in 2.00 seconds... (1/100)

[2025-02-25 09:48:46,941: ERROR/MainProcess] consumer: Cannot connect to redis://redis:6379//: Error -3 connecting to redis:6379. Temporary failure in name resolution..
Trying again in 4.00 seconds... (2/100)

[2025-02-25 09:49:52,823: WARNING/MainProcess] /usr/local/lib/python3.10/site-packages/celery/worker/consumer/consumer.py:508: CPendingDeprecationWarning: The broker_connection_retry configuration setting will no longer determine
whether broker connection retries are made during startup in Celery 6.0 and above.
If you wish to retain the existing behavior for retrying connections on startup,
you should set broker_connection_retry_on_startup to True.
  warnings.warn(

[2025-02-25 09:49:53,297: ERROR/MainProcess] consumer: Cannot connect to redis://redis:6379//: Error -3 connecting to redis:6379. Temporary failure in name resolution..
Trying again in 2.00 seconds... (1/100)

[2025-02-25 09:49:55,714: ERROR/MainProcess] consumer: Cannot connect to redis://redis:6379//: Error -3 connecting to redis:6379. Temporary failure in name resolution..
Trying again in 4.00 seconds... (2/100)

[2025-02-25 09:50:00,103: ERROR/MainProcess] consumer: Cannot connect to redis://redis:6379//: Error -3 connecting to redis:6379. Temporary failure in name resolution..
Trying again in 6.00 seconds... (3/100)

[2025-02-25 09:53:50,602: WARNING/MainProcess] /usr/local/lib/python3.10/site-packages/celery/worker/consumer/consumer.py:508: CPendingDeprecationWarning: The broker_connection_retry configuration setting will no longer determine
whether broker connection retries are made during startup in Celery 6.0 and above.
If you wish to retain the existing behavior for retrying connections on startup,
you should set broker_connection_retry_on_startup to True.
  warnings.warn(

[2025-02-25 09:53:53,711: ERROR/MainProcess] consumer: Cannot connect to redis://redis:6379//: Error 113 connecting to redis:6379. No route to host..
Trying again in 2.00 seconds... (1/100)

[2025-02-25 09:53:56,094: ERROR/MainProcess] consumer: Cannot connect to redis://redis:6379//: Error -3 connecting to redis:6379. Temporary failure in name resolution..
Trying again in 4.00 seconds... (2/100)

[2025-02-25 09:54:52,107: WARNING/MainProcess] /usr/local/lib/python3.10/site-packages/celery/worker/consumer/consumer.py:508: CPendingDeprecationWarning: The broker_connection_retry configuration setting will no longer determine
whether broker connection retries are made during startup in Celery 6.0 and above.
If you wish to retain the existing behavior for retrying connections on startup,
you should set broker_connection_retry_on_startup to True.
  warnings.warn(

[2025-02-25 09:54:52,555: ERROR/MainProcess] consumer: Cannot connect to redis://redis:6379//: Error -3 connecting to redis:6379. Temporary failure in name resolution..
Trying again in 2.00 seconds... (1/100)

[2025-02-25 09:54:54,925: ERROR/MainProcess] consumer: Cannot connect to redis://redis:6379//: Error -3 connecting to redis:6379. Temporary failure in name resolution..
Trying again in 4.00 seconds... (2/100)

[2025-02-25 09:54:59,526: ERROR/MainProcess] consumer: Cannot connect to redis://redis:6379//: Error -3 connecting to redis:6379. Temporary failure in name resolution..
Trying again in 6.00 seconds... (3/100)

[2025-02-25 09:55:11,733: WARNING/MainProcess] /usr/local/lib/python3.10/site-packages/celery/worker/consumer/consumer.py:508: CPendingDeprecationWarning: The broker_connection_retry configuration setting will no longer determine
whether broker connection retries are made during startup in Celery 6.0 and above.
If you wish to retain the existing behavior for retrying connections on startup,
you should set broker_connection_retry_on_startup to True.
  warnings.warn(

[2025-02-25 09:55:12,101: ERROR/MainProcess] consumer: Cannot connect to redis://redis:6379//: Error -3 connecting to redis:6379. Temporary failure in name resolution..
Trying again in 2.00 seconds... (1/100)

[2025-02-25 09:55:14,516: ERROR/MainProcess] consumer: Cannot connect to redis://redis:6379//: Error -3 connecting to redis:6379. Temporary failure in name resolution..
Trying again in 4.00 seconds... (2/100)

[2025-02-25 09:59:22,429: WARNING/MainProcess] /usr/local/lib/python3.10/site-packages/celery/worker/consumer/consumer.py:508: CPendingDeprecationWarning: The broker_connection_retry configuration setting will no longer determine
whether broker connection retries are made during startup in Celery 6.0 and above.
If you wish to retain the existing behavior for retrying connections on startup,
you should set broker_connection_retry_on_startup to True.
  warnings.warn(

[2025-02-25 09:59:22,832: ERROR/MainProcess] consumer: Cannot connect to redis://redis:6379//: Error -3 connecting to redis:6379. Temporary failure in name resolution..
Trying again in 2.00 seconds... (1/100)

[2025-02-25 09:59:25,226: ERROR/MainProcess] consumer: Cannot connect to redis://redis:6379//: Error -3 connecting to redis:6379. Temporary failure in name resolution..
Trying again in 4.00 seconds... (2/100)

[2025-02-25 09:59:29,604: ERROR/MainProcess] consumer: Cannot connect to redis://redis:6379//: Error -3 connecting to redis:6379. Temporary failure in name resolution..
Trying again in 6.00 seconds... (3/100)

[2025-02-25 10:01:37,408: WARNING/MainProcess] /usr/local/lib/python3.10/site-packages/celery/worker/consumer/consumer.py:508: CPendingDeprecationWarning: The broker_connection_retry configuration setting will no longer determine
whether broker connection retries are made during startup in Celery 6.0 and above.
If you wish to retain the existing behavior for retrying connections on startup,
you should set broker_connection_retry_on_startup to True.
  warnings.warn(

[2025-02-25 10:01:37,780: ERROR/MainProcess] consumer: Cannot connect to redis://redis:6379/1: Error -3 connecting to redis:6379. Temporary failure in name resolution..
Trying again in 2.00 seconds... (1/100)

[2025-02-25 10:01:40,196: ERROR/MainProcess] consumer: Cannot connect to redis://redis:6379/1: Error -3 connecting to redis:6379. Temporary failure in name resolution..
Trying again in 4.00 seconds... (2/100)

[2025-02-25 10:01:44,671: ERROR/MainProcess] consumer: Cannot connect to redis://redis:6379/1: Error -3 connecting to redis:6379. Temporary failure in name resolution..
Trying again in 6.00 seconds... (3/100)

[2025-02-25 10:05:28,082: WARNING/MainProcess] /usr/local/lib/python3.10/site-packages/celery/worker/consumer/consumer.py:508: CPendingDeprecationWarning: The broker_connection_retry configuration setting will no longer determine
whether broker connection retries are made during startup in Celery 6.0 and above.
If you wish to retain the existing behavior for retrying connections on startup,
you should set broker_connection_retry_on_startup to True.
  warnings.warn(

[2025-02-25 10:05:28,505: ERROR/MainProcess] consumer: Cannot connect to redis://redis:6379/0: Error -3 connecting to redis:6379. Temporary failure in name resolution..
Trying again in 2.00 seconds... (1/100)

[2025-02-25 10:05:30,922: ERROR/MainProcess] consumer: Cannot connect to redis://redis:6379/0: Error -3 connecting to redis:6379. Temporary failure in name resolution..
Trying again in 4.00 seconds... (2/100)

[2025-02-25 10:06:40,289: WARNING/MainProcess] /usr/local/lib/python3.10/site-packages/celery/worker/consumer/consumer.py:508: CPendingDeprecationWarning: The broker_connection_retry configuration setting will no longer determine
whether broker connection retries are made during startup in Celery 6.0 and above.
If you wish to retain the existing behavior for retrying connections on startup,
you should set broker_connection_retry_on_startup to True.
  warnings.warn(

[2025-02-25 10:06:40,301: INFO/MainProcess] Connected to redis://redis:6379/0
[2025-02-25 10:06:40,302: WARNING/MainProcess] /usr/local/lib/python3.10/site-packages/celery/worker/consumer/consumer.py:508: CPendingDeprecationWarning: The broker_connection_retry configuration setting will no longer determine
whether broker connection retries are made during startup in Celery 6.0 and above.
If you wish to retain the existing behavior for retrying connections on startup,
you should set broker_connection_retry_on_startup to True.
  warnings.warn(

[2025-02-25 10:06:40,304: INFO/MainProcess] mingle: searching for neighbors
[2025-02-25 10:06:41,316: INFO/MainProcess] mingle: all alone
[2025-02-25 10:06:41,323: INFO/MainProcess] celery@1c470f00a010 ready.
[2025-02-25 10:06:42,404: INFO/MainProcess] Events of group {task} enabled by remote.
[2025-02-25 10:16:37,585: INFO/MainProcess] Task user.tasks.send_new_user_email[dbb16ab9-8e99-4af0-8efd-a290152f70a6] received
[2025-02-25 10:16:40,336: ERROR/ForkPoolWorker-7] Task user.tasks.send_new_user_email[dbb16ab9-8e99-4af0-8efd-a290152f70a6] raised unexpected: SMTPAuthenticationError(535, b'5.7.8 Username and Password not accepted. For more information, go to\n5.7.8  https://support.google.com/mail/?p=BadCredentials a640c23a62f3a-abed204f6edsm113321166b.128 - gsmtp')
Traceback (most recent call last):
  File "/usr/local/lib/python3.10/site-packages/celery/app/trace.py", line 453, in trace_task
    R = retval = fun(*args, **kwargs)
  File "/usr/local/lib/python3.10/site-packages/celery/app/trace.py", line 736, in __protected_call__
    return self.run(*args, **kwargs)
  File "/app/user/tasks.py", line 16, in send_new_user_email
    send_email('Verify Email',
  File "/app/user/utils.py", line 10, in send_email
    msg.send(fail_silently=False)
  File "/usr/local/lib/python3.10/site-packages/django/core/mail/message.py", line 301, in send
    return self.get_connection(fail_silently).send_messages([self])
  File "/usr/local/lib/python3.10/site-packages/django/core/mail/backends/smtp.py", line 128, in send_messages
    new_conn_created = self.open()
  File "/usr/local/lib/python3.10/site-packages/django/core/mail/backends/smtp.py", line 95, in open
    self.connection.login(self.username, self.password)
  File "/usr/local/lib/python3.10/smtplib.py", line 750, in login
    raise last_exception
  File "/usr/local/lib/python3.10/smtplib.py", line 739, in login
    (code, resp) = self.auth(
  File "/usr/local/lib/python3.10/smtplib.py", line 662, in auth
    raise SMTPAuthenticationError(code, resp)
smtplib.SMTPAuthenticationError: (535, b'5.7.8 Username and Password not accepted. For more information, go to\n5.7.8  https://support.google.com/mail/?p=BadCredentials a640c23a62f3a-abed204f6edsm113321166b.128 - gsmtp')
[2025-02-25 10:25:56,876: WARNING/MainProcess] /usr/local/lib/python3.10/site-packages/celery/worker/consumer/consumer.py:508: CPendingDeprecationWarning: The broker_connection_retry configuration setting will no longer determine
whether broker connection retries are made during startup in Celery 6.0 and above.
If you wish to retain the existing behavior for retrying connections on startup,
you should set broker_connection_retry_on_startup to True.
  warnings.warn(

[2025-02-25 10:25:56,888: INFO/MainProcess] Connected to redis://redis:6379/0
[2025-02-25 10:25:56,889: WARNING/MainProcess] /usr/local/lib/python3.10/site-packages/celery/worker/consumer/consumer.py:508: CPendingDeprecationWarning: The broker_connection_retry configuration setting will no longer determine
whether broker connection retries are made during startup in Celery 6.0 and above.
If you wish to retain the existing behavior for retrying connections on startup,
you should set broker_connection_retry_on_startup to True.
  warnings.warn(

[2025-02-25 10:25:56,891: INFO/MainProcess] mingle: searching for neighbors
[2025-02-25 10:25:57,899: INFO/MainProcess] mingle: all alone
[2025-02-25 10:25:57,925: INFO/MainProcess] celery@8b2c6eeade56 ready.
[2025-02-25 10:25:58,916: INFO/MainProcess] Events of group {task} enabled by remote.
[2025-02-25 10:26:29,171: INFO/MainProcess] Task user.tasks.send_new_user_email[57493679-13d6-481d-9076-8a0521a285de] received
[2025-02-25 10:26:33,089: INFO/ForkPoolWorker-7] Task user.tasks.send_new_user_email[57493679-13d6-481d-9076-8a0521a285de] succeeded in 3.9166674119987874s: None
[2025-02-25 10:30:44,519: INFO/MainProcess] Task user.tasks.send_password_reset_email[0bde8b44-240e-4fdd-acbe-8a8b51764c15] received
[2025-02-25 10:30:47,447: INFO/ForkPoolWorker-7] Task user.tasks.send_password_reset_email[0bde8b44-240e-4fdd-acbe-8a8b51764c15] succeeded in 2.9263268989998323s: None
[2025-02-25 10:32:48,260: INFO/MainProcess] Task user.tasks.send_password_reset_email[6da96235-ad76-464d-b09b-f46ddab47932] received
[2025-02-25 10:32:51,140: INFO/ForkPoolWorker-7] Task user.tasks.send_password_reset_email[6da96235-ad76-464d-b09b-f46ddab47932] succeeded in 2.8781312690007326s: None
